<?xml version="1.0"?>
<robot name="robot">
    <link name="base_link">
        <visual>
            <geometry>
                <box size="0.6 0.4 0.8" />
            </geometry>
            <origin xyz="0 0 0.4" rpy="0 0 0" />
        </visual>
    </link>
    <link name="lidar">
        <visual>
            <geometry>
                <cylinder radius="0.1" length="0.05"/>
            </geometry>
            <origin xyz="0 0 0" rpy="0 0 0" />
            <material name="green" />
        </visual>
    </link>
    <material name="green">
        <color rgba="0 0.9 0 1" />
    </material>
    <material name="white">
        <color rgba="1 1 1 1" />
    </material>
    <material name="grey">
        <color rgba="0.7 0.7 0.7 1" />
    </material>
    <joint name="base_Lidar_joint" type="fixed">
        <parent link="base_link"/>
        <child link="lidar" />
        <origin xyz="0 0 0.825" rpy="0 0 0"/>
    </joint>
    <link name="left_wheel">
        <visual>
            <geometry>
                <cylinder radius="0.1" length="0.05"/>
            </geometry>
            <origin xyz="0 0 0" rpy="1.57 0 0" />
            <material name="grey" />
        </visual>
    </link>
    <link name="right_wheel">
        <visual>
            <geometry>
                <cylinder radius="0.1" length="0.05"/>
            </geometry>
            <origin xyz="0 0 0" rpy="1.57 0 0" />
            <material name="grey" />
        </visual>
    </link>
    <joint name="base_left_wheel_joint" type="continuous">
        <parent link="base_link" />
        <child link="left_wheel"/>
        <origin xyz="-0.15 0.225 0" rpy="0 0 0" />
        <axis xyz="0 1 0" />
    </joint>

    <joint name="base_right_wheel_joint" type="continuous">
        <parent link="base_link" />
        <child link="right_wheel"/>
        <origin xyz="-0.15 -0.225 0" rpy="0 0 0" />
        <axis xyz="0 1 0" />
    </joint>

    <link name="caster_wheel">
        <visual>
            <geometry>
                <sphere radius="0.05"/>
            </geometry>
            <origin xyz="0 0 0" rpy="0 0 0" />
            <material name="grey" />
        </visual>
    </link>

    <joint name="base_caster_wheel_joint" type="fixed">
        <parent link="base_link" />
        <child link = "caster_wheel"/>
        <origin xyz="0.2 0 -0.05" rpy="0 0 0" />
    </joint>


</robot>