<?xml version="1.0"?>
<robot name="robot">

    <link name="base_link">
        <visual>
            <geometry>
                <box size="0.6 0.4 0.8" />
            </geometry>
            <origin xyz="0 0 0.4" rpy="0 0 0" />
        </visual>
        <collision>
            <geometry>
                <box size="0.6 0.4 0.8" />
            </geometry>
            <origin xyz="0 0 0.4" rpy="0 0 0" />
        </collision>
        <inertial>
            <mass value="5.0" />
            <origin xyz="0 0 0.4" rpy="0 0 0" />
            <inertia ixx="0.3" ixy="0" ixz="0"
                                iyy="0.4" iyz="0"
                                        izz="0.2" />
        </inertial>
    </link>

    <link name="lidar">
        <visual>
            <geometry>
                <cylinder radius="0.1" length="0.05"/>
            </geometry>
            <origin xyz="0 0 0" rpy="0 0 0" />
            <material name="green" />
        </visual>
        <collision>
            <geometry>
                <cylinder radius="0.1" length="0.05"/>
            </geometry>
            <origin xyz="0 0 0" rpy="0 0 0" />
        </collision>
        <inertial>
            <mass value="0.1" />
            <origin xyz="0 0 0" rpy="0 0 0" />
            <inertia ixx="0.0001" ixy="0" ixz="0"
                                iyy="0.0001" iyz="0"
                                            izz="0.0001" />
        </inertial>
    </link>

    <material name="green">
        <color rgba="0 0.9 0 1" />
    </material>
    <material name="white">
        <color rgba="1 1 1 1" />
    </material>
    <material name="grey">
        <color rgba="0.7 0.7 0.7 1" />
    </material>

    <joint name="base_Lidar_joint" type="fixed">
        <parent link="base_link"/>
        <child link="lidar" />
        <origin xyz="0 0 0.825" rpy="0 0 0"/>
    </joint>

    <link name="left_wheel">
        <visual>
            <geometry>
                <cylinder radius="0.1" length="0.05"/>
            </geometry>
            <origin xyz="0 0 0" rpy="1.57 0 0" />
            <material name="grey" />
        </visual>
        <collision>
            <geometry>
                <cylinder radius="0.1" length="0.05"/>
            </geometry>
            <origin xyz="0 0 0" rpy="1.57 0 0" />
        </collision>
        <inertial>
            <mass value="0.5" />
            <origin xyz="0 0 0" rpy="0 0 0" />
            <inertia ixx="0.001" ixy="0" ixz="0"
                                iyy="0.001" iyz="0"
                                            izz="0.001" />
        </inertial>
    </link>

    <link name="right_wheel">
        <visual>
            <geometry>
                <cylinder radius="0.1" length="0.05"/>
            </geometry>
            <origin xyz="0 0 0" rpy="1.57 0 0" />
            <material name="grey" />
        </visual>
                <collision>
            <geometry>
                <cylinder radius="0.1" length="0.05"/>
            </geometry>
            <origin xyz="0 0 0" rpy="1.57 0 0" />
        </collision>
        <inertial>
            <mass value="0.5" />
            <origin xyz="0 0 0" rpy="0 0 0" />
            <inertia ixx="0.001" ixy="0" ixz="0"
                                iyy="0.001" iyz="0"
                                            izz="0.001" />
        </inertial>
    </link>

    <joint name="base_left_wheel_joint" type="continuous">
        <parent link="base_link" />
        <child link="left_wheel"/>
        <origin xyz="-0.15 0.225 0" rpy="0 0 0" />
        <axis xyz="0 1 0" />
    </joint>

    <joint name="base_right_wheel_joint" type="continuous">
        <parent link="base_link" />
        <child link="right_wheel"/>
        <origin xyz="-0.15 -0.225 0" rpy="0 0 0" />
        <axis xyz="0 1 0" />
    </joint>

    <link name="caster_wheel">
        <visual>
            <geometry>
                <sphere radius="0.05"/>
            </geometry>
            <origin xyz="0 0 0" rpy="0 0 0" />
            <material name="grey" />
        </visual>
        <collision>
            <geometry>
                <sphere radius="0.05"/>
            </geometry>
            <origin xyz="0 0 0" rpy="0 0 0" />
        </collision>
        <inertial>
            <mass value="0.1" />
            <origin xyz="0 0 0" rpy="0 0 0" />
            <inertia ixx="0.0001" ixy="0" ixz="0"
                                iyy="0.0001" iyz="0"
                                            izz="0.0001" />
        </inertial>
    </link>

    <joint name="base_caster_wheel_joint" type="fixed">
        <parent link="base_link" />
        <child link = "caster_wheel"/>
        <origin xyz="0.2 0 -0.05" rpy="0 0 0" />
    </joint>

    <link name="base_footprint" />

    <joint name="base_joint" type="fixed">
        <parent link="base_footprint" />
        <child link = "base_link"/>
        <origin xyz="0 0 0.4" rpy="0 0 0" />
    </joint>

    <gazebo>
        <plugin filename="gz-sim-diff-drive-system"
                name="gz::sim::systems::DiffDrive">
            <left_joint>base_left_wheel_joint</left_joint>
            <right_joint>base_right_wheel_joint</right_joint>
            <wheel_separation>0.45</wheel_separation>
            <wheel_radius>0.1</wheel_radius>
            <topic>/cmd_vel</topic>
            <odom_topic>/odom</odom_topic>
            <frame_id>odom</frame_id>
            <child_frame_id>base_footprint</child_frame_id>
        </plugin>
    </gazebo>

    <gazebo reference="lidar">
        <sensor name="lidar_sensor" type="gpu_lidar">
            <pose>0 0 0 0 0 0</pose>
            <topic>/scan</topic>
            <update_rate>10</update_rate>
            <lidar>
                <scan>
                    <horizontal>
                        <samples>360</samples>
                        <resolution>1</resolution>
                        <min_angle>-3.14159</min_angle>
                        <max_angle>3.14159</max_angle>
                    </horizontal>
                </scan>
                <range>
                    <min>0.12</min>
                    <max>10.0</max>
                    <resolution>0.01</resolution>
                </range>
            </lidar>
            <alwaysOn>true</alwaysOn>
            <visualize>true</visualize>
            <plugin filename="gz-sim-sensors-system"
                    name="gz::sim::systems::Sensors">
                <render_engine>ogre2</render_engine>
            </plugin>
        </sensor>
    </gazebo>

    <gazebo reference="caster_wheel">
        <mu1>0.0</mu1>
        <mu2>0.0</mu2>
    </gazebo>

    <gazebo reference="base_link">
        <visual>
            <material>
                <ambient>1 1 1 1</ambient>
                <diffuse>1 1 1 1</diffuse>
                <pbr>
                    <metal>
                        <albedo_map>model://model/worlds/textures/robottexture.png</albedo_map>
                    </metal>
                </pbr>
            </material>
        </visual>
    </gazebo>

    <gazebo reference="lidar">
        <visual>
            <material>
                <ambient>1 1 1 1</ambient>
                <diffuse>1 1 1 1</diffuse>
                <pbr>
                    <metal>
                        <albedo_map>model://model/worlds/textures/lidartexture.png</albedo_map>
                    </metal>
                </pbr>
            </material>
        </visual>
    </gazebo>

    <gazebo reference="right_wheel">
        <visual>
            <material>
                <ambient>1 1 1 1</ambient>
                <diffuse>1 1 1 1</diffuse>
                <pbr>
                    <metal>
                        <albedo_map>model://model/worlds/textures/lidartexture.png</albedo_map>
                    </metal>
                </pbr>
            </material>
        </visual>
    </gazebo>

    <gazebo reference="left_wheel">
        <visual>
            <material>
                <ambient>1 1 1 1</ambient>
                <diffuse>1 1 1 1</diffuse>
                <pbr>
                    <metal>
                        <albedo_map>model://model/worlds/textures/lidartexture.png</albedo_map>
                    </metal>
                </pbr>
            </material>
        </visual>
    </gazebo>

</robot>